<?xml version="1.0" encoding="UTF-8"?>
<testng-results skipped="0" failed="5" ignored="0" total="6" passed="1">
  <reporter-output>
  </reporter-output>
  <suite name="用户管理系统" duration-ms="20935" started-at="2020-04-01T22:41:05 CST" finished-at="2020-04-01T22:41:26 CST">
    <groups>
    </groups>
    <test name="用户管理系统接口" duration-ms="20935" started-at="2020-04-01T22:41:05 CST" finished-at="2020-04-01T22:41:26 CST">
      <class name="itest.WebTest">
        <test-method status="PASS" signature="BeforeClass()[pri:0, instance:itest.WebTest@29647f75]" name="BeforeClass" is-config="true" duration-ms="0" started-at="2020-04-01T22:41:16 CST" finished-at="2020-04-01T22:41:16 CST">
          <reporter-output>
          </reporter-output>
        </test-method> <!-- BeforeClass -->
        <test-method status="PASS" signature="f(webCaseModel.CaseModel)[pri:0, instance:itest.WebTest@29647f75, instance params:[]]" name="f" duration-ms="10343" started-at="2020-04-01T22:41:16 CST" data-provider="dp" finished-at="2020-04-01T22:41:26 CST">
          <params>
            <param index="0">
              <value>
                <![CDATA[CaseModel [caseName=百度搜索, stepModels=[StepModel [step=打开百度首页, Element=ElementModel [elementName=百度url, elementValue=http://www.baidu.com/, elementByType=url]
, action=get
, value=null, expect=null]
, StepModel [step=输入测试, Element=ElementModel [elementName=搜索输入框, elementValue=//*[@id="kw"], elementByType=XPath]
, action=sendkeys
, value=测试, expect=null]
, StepModel [step=点击搜索, Element=ElementModel [elementName=搜索按钮, elementValue=//*[@id="su"], elementByType=XPath]
, action=click
, value=null, expect=null]
, StepModel [step=检查搜索结果, Element=ElementModel [elementName=关键字标记, elementValue=//em[1], elementByType=XPath]
, action=gettext
, value=测试, expect=测试]
]]]]>
              </value>
            </param>
          </params>
          <reporter-output>
          </reporter-output>
        </test-method> <!-- f -->
        <test-method status="PASS" signature="AfterClass()[pri:0, instance:itest.WebTest@29647f75]" name="AfterClass" is-config="true" duration-ms="1" started-at="2020-04-01T22:41:26 CST" finished-at="2020-04-01T22:41:26 CST">
          <reporter-output>
          </reporter-output>
        </test-method> <!-- AfterClass -->
      </class> <!-- itest.WebTest -->
      <class name="itest.APITest">
        <test-method status="FAIL" signature="run(apiModel.APICaseModel)[pri:0, instance:itest.APITest@2525ff7e, instance params:[]]" name="run" duration-ms="2233" started-at="2020-04-01T22:41:05 CST" data-provider="dp" finished-at="2020-04-01T22:41:07 CST">
          <params>
            <param index="0">
              <value>
                <![CDATA[CaseModel [caseName=用户登陆接口,stepModels=[StepModel [step=用户登陆,url=http://localhost:8080/user/login,action=post
,value={param:{'username':'lewis','password':'123'}},expect=true]
]]
]]>
              </value>
            </param>
          </params>
          <exception class="java.lang.AssertionError">
            <message>
              <![CDATA[expected [true] but found [请求错误]]]>
            </message>
            <full-stacktrace>
              <![CDATA[java.lang.AssertionError: expected [true] but found [请求错误]
at org.testng.Assert.fail(Assert.java:97)
at org.testng.Assert.assertEqualsImpl(Assert.java:136)
at org.testng.Assert.assertEquals(Assert.java:118)
at org.testng.Assert.assertEquals(Assert.java:575)
at org.testng.Assert.assertEquals(Assert.java:585)
at itest.APITest.doCase(APITest.java:37)
at itest.APITest.run(APITest.java:25)
at sun.reflect.NativeMethodAccessorImpl.invoke0(Native Method)
at sun.reflect.NativeMethodAccessorImpl.invoke(NativeMethodAccessorImpl.java:62)
at sun.reflect.DelegatingMethodAccessorImpl.invoke(DelegatingMethodAccessorImpl.java:43)
at java.lang.reflect.Method.invoke(Method.java:498)
at org.testng.internal.MethodInvocationHelper.invokeMethod(MethodInvocationHelper.java:133)
at org.testng.internal.TestInvoker.invokeMethod(TestInvoker.java:584)
at org.testng.internal.TestInvoker.invokeTestMethod(TestInvoker.java:172)
at org.testng.internal.MethodRunner.runInSequence(MethodRunner.java:46)
at org.testng.internal.TestInvoker$MethodInvocationAgent.invoke(TestInvoker.java:804)
at org.testng.internal.TestInvoker.invokeTestMethods(TestInvoker.java:145)
at org.testng.internal.TestMethodWorker.invokeTestMethods(TestMethodWorker.java:146)
at org.testng.internal.TestMethodWorker.run(TestMethodWorker.java:128)
at java.util.ArrayList.forEach(ArrayList.java:1257)
at org.testng.TestRunner.privateRun(TestRunner.java:770)
at org.testng.TestRunner.run(TestRunner.java:591)
at org.testng.SuiteRunner.runTest(SuiteRunner.java:402)
at org.testng.SuiteRunner.runSequentially(SuiteRunner.java:396)
at org.testng.SuiteRunner.privateRun(SuiteRunner.java:355)
at org.testng.SuiteRunner.run(SuiteRunner.java:304)
at org.testng.SuiteRunnerWorker.runSuite(SuiteRunnerWorker.java:53)
at org.testng.SuiteRunnerWorker.run(SuiteRunnerWorker.java:96)
at org.testng.TestNG.runSuitesSequentially(TestNG.java:1180)
at org.testng.TestNG.runSuitesLocally(TestNG.java:1102)
at org.testng.TestNG.runSuites(TestNG.java:1032)
at org.testng.TestNG.run(TestNG.java:1000)
at org.testng.remote.AbstractRemoteTestNG.run(AbstractRemoteTestNG.java:115)
at org.testng.remote.RemoteTestNG.initAndRun(RemoteTestNG.java:251)
at org.testng.remote.RemoteTestNG.main(RemoteTestNG.java:77)
]]>
            </full-stacktrace>
          </exception> <!-- java.lang.AssertionError -->
          <reporter-output>
          </reporter-output>
        </test-method> <!-- run -->
        <test-method status="FAIL" signature="run(apiModel.APICaseModel)[pri:0, instance:itest.APITest@2525ff7e, instance params:[]]" name="run" duration-ms="2073" started-at="2020-04-01T22:41:07 CST" data-provider="dp" finished-at="2020-04-01T22:41:09 CST">
          <params>
            <param index="0">
              <value>
                <![CDATA[CaseModel [caseName=查询用户数接口,stepModels=[StepModel [step=查询用户数量,url=http://localhost:8080/user/getusercount,action=get
,value=null,expect=8]
]]
]]>
              </value>
            </param>
          </params>
          <exception class="java.lang.AssertionError">
            <message>
              <![CDATA[expected [8] but found [请求异常，发生错误！]]]>
            </message>
            <full-stacktrace>
              <![CDATA[java.lang.AssertionError: expected [8] but found [请求异常，发生错误！]
at org.testng.Assert.fail(Assert.java:97)
at org.testng.Assert.assertEqualsImpl(Assert.java:136)
at org.testng.Assert.assertEquals(Assert.java:118)
at org.testng.Assert.assertEquals(Assert.java:575)
at org.testng.Assert.assertEquals(Assert.java:585)
at itest.APITest.doCase(APITest.java:34)
at itest.APITest.run(APITest.java:25)
at sun.reflect.NativeMethodAccessorImpl.invoke0(Native Method)
at sun.reflect.NativeMethodAccessorImpl.invoke(NativeMethodAccessorImpl.java:62)
at sun.reflect.DelegatingMethodAccessorImpl.invoke(DelegatingMethodAccessorImpl.java:43)
at java.lang.reflect.Method.invoke(Method.java:498)
at org.testng.internal.MethodInvocationHelper.invokeMethod(MethodInvocationHelper.java:133)
at org.testng.internal.TestInvoker.invokeMethod(TestInvoker.java:584)
at org.testng.internal.TestInvoker.invokeTestMethod(TestInvoker.java:172)
at org.testng.internal.MethodRunner.runInSequence(MethodRunner.java:46)
at org.testng.internal.TestInvoker$MethodInvocationAgent.invoke(TestInvoker.java:804)
at org.testng.internal.TestInvoker.invokeTestMethods(TestInvoker.java:145)
at org.testng.internal.TestMethodWorker.invokeTestMethods(TestMethodWorker.java:146)
at org.testng.internal.TestMethodWorker.run(TestMethodWorker.java:128)
at java.util.ArrayList.forEach(ArrayList.java:1257)
at org.testng.TestRunner.privateRun(TestRunner.java:770)
at org.testng.TestRunner.run(TestRunner.java:591)
at org.testng.SuiteRunner.runTest(SuiteRunner.java:402)
at org.testng.SuiteRunner.runSequentially(SuiteRunner.java:396)
at org.testng.SuiteRunner.privateRun(SuiteRunner.java:355)
at org.testng.SuiteRunner.run(SuiteRunner.java:304)
at org.testng.SuiteRunnerWorker.runSuite(SuiteRunnerWorker.java:53)
at org.testng.SuiteRunnerWorker.run(SuiteRunnerWorker.java:96)
at org.testng.TestNG.runSuitesSequentially(TestNG.java:1180)
at org.testng.TestNG.runSuitesLocally(TestNG.java:1102)
at org.testng.TestNG.runSuites(TestNG.java:1032)
at org.testng.TestNG.run(TestNG.java:1000)
at org.testng.remote.AbstractRemoteTestNG.run(AbstractRemoteTestNG.java:115)
at org.testng.remote.RemoteTestNG.initAndRun(RemoteTestNG.java:251)
at org.testng.remote.RemoteTestNG.main(RemoteTestNG.java:77)
]]>
            </full-stacktrace>
          </exception> <!-- java.lang.AssertionError -->
          <reporter-output>
          </reporter-output>
        </test-method> <!-- run -->
        <test-method status="FAIL" signature="run(apiModel.APICaseModel)[pri:0, instance:itest.APITest@2525ff7e, instance params:[]]" name="run" duration-ms="2074" started-at="2020-04-01T22:41:09 CST" data-provider="dp" finished-at="2020-04-01T22:41:11 CST">
          <params>
            <param index="0">
              <value>
                <![CDATA[CaseModel [caseName=获取用户信息,stepModels=[StepModel [step=获取用户信息,url=http://localhost:8080/user/getUserInfo,action=post
,value={param:{'id':'1'},header:{'cookie':'login=true'}},expect=[{"id":1,"username":"lewis","password":"123","sex":"0","age":"33","permission":"1","isDelete":"0"}]]
]]
]]>
              </value>
            </param>
          </params>
          <exception class="java.lang.AssertionError">
            <message>
              <![CDATA[expected [[{"id":1,"username":"lewis","password":"123","sex":"0","age":"33","permission":"1","isDelete":"0"}]] but found [请求错误]]]>
            </message>
            <full-stacktrace>
              <![CDATA[java.lang.AssertionError: expected [[{"id":1,"username":"lewis","password":"123","sex":"0","age":"33","permission":"1","isDelete":"0"}]] but found [请求错误]
at org.testng.Assert.fail(Assert.java:97)
at org.testng.Assert.assertEqualsImpl(Assert.java:136)
at org.testng.Assert.assertEquals(Assert.java:118)
at org.testng.Assert.assertEquals(Assert.java:575)
at org.testng.Assert.assertEquals(Assert.java:585)
at itest.APITest.doCase(APITest.java:37)
at itest.APITest.run(APITest.java:25)
at sun.reflect.NativeMethodAccessorImpl.invoke0(Native Method)
at sun.reflect.NativeMethodAccessorImpl.invoke(NativeMethodAccessorImpl.java:62)
at sun.reflect.DelegatingMethodAccessorImpl.invoke(DelegatingMethodAccessorImpl.java:43)
at java.lang.reflect.Method.invoke(Method.java:498)
at org.testng.internal.MethodInvocationHelper.invokeMethod(MethodInvocationHelper.java:133)
at org.testng.internal.TestInvoker.invokeMethod(TestInvoker.java:584)
at org.testng.internal.TestInvoker.invokeTestMethod(TestInvoker.java:172)
at org.testng.internal.MethodRunner.runInSequence(MethodRunner.java:46)
at org.testng.internal.TestInvoker$MethodInvocationAgent.invoke(TestInvoker.java:804)
at org.testng.internal.TestInvoker.invokeTestMethods(TestInvoker.java:145)
at org.testng.internal.TestMethodWorker.invokeTestMethods(TestMethodWorker.java:146)
at org.testng.internal.TestMethodWorker.run(TestMethodWorker.java:128)
at java.util.ArrayList.forEach(ArrayList.java:1257)
at org.testng.TestRunner.privateRun(TestRunner.java:770)
at org.testng.TestRunner.run(TestRunner.java:591)
at org.testng.SuiteRunner.runTest(SuiteRunner.java:402)
at org.testng.SuiteRunner.runSequentially(SuiteRunner.java:396)
at org.testng.SuiteRunner.privateRun(SuiteRunner.java:355)
at org.testng.SuiteRunner.run(SuiteRunner.java:304)
at org.testng.SuiteRunnerWorker.runSuite(SuiteRunnerWorker.java:53)
at org.testng.SuiteRunnerWorker.run(SuiteRunnerWorker.java:96)
at org.testng.TestNG.runSuitesSequentially(TestNG.java:1180)
at org.testng.TestNG.runSuitesLocally(TestNG.java:1102)
at org.testng.TestNG.runSuites(TestNG.java:1032)
at org.testng.TestNG.run(TestNG.java:1000)
at org.testng.remote.AbstractRemoteTestNG.run(AbstractRemoteTestNG.java:115)
at org.testng.remote.RemoteTestNG.initAndRun(RemoteTestNG.java:251)
at org.testng.remote.RemoteTestNG.main(RemoteTestNG.java:77)
]]>
            </full-stacktrace>
          </exception> <!-- java.lang.AssertionError -->
          <reporter-output>
          </reporter-output>
        </test-method> <!-- run -->
        <test-method status="FAIL" signature="run(apiModel.APICaseModel)[pri:0, instance:itest.APITest@524d6d96, instance params:[]]" name="run" duration-ms="2053" started-at="2020-04-01T22:41:11 CST" data-provider="dp" finished-at="2020-04-01T22:41:14 CST">
          <params>
            <param index="0">
              <value>
                <![CDATA[CaseModel [caseName=用户登陆接口,stepModels=[StepModel [step=用户登陆,url=http://localhost:8080/user/login,action=post
,value={param:{'username':'lewis','password':'123'}},expect=true]
]]
]]>
              </value>
            </param>
          </params>
          <exception class="java.lang.AssertionError">
            <message>
              <![CDATA[expected [true] but found [请求错误]]]>
            </message>
            <full-stacktrace>
              <![CDATA[java.lang.AssertionError: expected [true] but found [请求错误]
at org.testng.Assert.fail(Assert.java:97)
at org.testng.Assert.assertEqualsImpl(Assert.java:136)
at org.testng.Assert.assertEquals(Assert.java:118)
at org.testng.Assert.assertEquals(Assert.java:575)
at org.testng.Assert.assertEquals(Assert.java:585)
at itest.APITest.doCase(APITest.java:37)
at itest.APITest.run(APITest.java:25)
at sun.reflect.NativeMethodAccessorImpl.invoke0(Native Method)
at sun.reflect.NativeMethodAccessorImpl.invoke(NativeMethodAccessorImpl.java:62)
at sun.reflect.DelegatingMethodAccessorImpl.invoke(DelegatingMethodAccessorImpl.java:43)
at java.lang.reflect.Method.invoke(Method.java:498)
at org.testng.internal.MethodInvocationHelper.invokeMethod(MethodInvocationHelper.java:133)
at org.testng.internal.TestInvoker.invokeMethod(TestInvoker.java:584)
at org.testng.internal.TestInvoker.invokeTestMethod(TestInvoker.java:172)
at org.testng.internal.MethodRunner.runInSequence(MethodRunner.java:46)
at org.testng.internal.TestInvoker$MethodInvocationAgent.invoke(TestInvoker.java:804)
at org.testng.internal.TestInvoker.invokeTestMethods(TestInvoker.java:145)
at org.testng.internal.TestMethodWorker.invokeTestMethods(TestMethodWorker.java:146)
at org.testng.internal.TestMethodWorker.run(TestMethodWorker.java:128)
at java.util.ArrayList.forEach(ArrayList.java:1257)
at org.testng.TestRunner.privateRun(TestRunner.java:770)
at org.testng.TestRunner.run(TestRunner.java:591)
at org.testng.SuiteRunner.runTest(SuiteRunner.java:402)
at org.testng.SuiteRunner.runSequentially(SuiteRunner.java:396)
at org.testng.SuiteRunner.privateRun(SuiteRunner.java:355)
at org.testng.SuiteRunner.run(SuiteRunner.java:304)
at org.testng.SuiteRunnerWorker.runSuite(SuiteRunnerWorker.java:53)
at org.testng.SuiteRunnerWorker.run(SuiteRunnerWorker.java:96)
at org.testng.TestNG.runSuitesSequentially(TestNG.java:1180)
at org.testng.TestNG.runSuitesLocally(TestNG.java:1102)
at org.testng.TestNG.runSuites(TestNG.java:1032)
at org.testng.TestNG.run(TestNG.java:1000)
at org.testng.remote.AbstractRemoteTestNG.run(AbstractRemoteTestNG.java:115)
at org.testng.remote.RemoteTestNG.initAndRun(RemoteTestNG.java:251)
at org.testng.remote.RemoteTestNG.main(RemoteTestNG.java:77)
]]>
            </full-stacktrace>
          </exception> <!-- java.lang.AssertionError -->
          <reporter-output>
          </reporter-output>
        </test-method> <!-- run -->
        <test-method status="FAIL" signature="run(apiModel.APICaseModel)[pri:0, instance:itest.APITest@524d6d96, instance params:[]]" name="run" duration-ms="2072" started-at="2020-04-01T22:41:14 CST" data-provider="dp" finished-at="2020-04-01T22:41:16 CST">
          <params>
            <param index="0">
              <value>
                <![CDATA[CaseModel [caseName=查询用户数接口,stepModels=[StepModel [step=查询用户数量,url=http://localhost:8080/user/getusercount,action=get
,value=null,expect=8]
]]
]]>
              </value>
            </param>
          </params>
          <exception class="java.lang.AssertionError">
            <message>
              <![CDATA[expected [8] but found [请求异常，发生错误！]]]>
            </message>
            <full-stacktrace>
              <![CDATA[java.lang.AssertionError: expected [8] but found [请求异常，发生错误！]
at org.testng.Assert.fail(Assert.java:97)
at org.testng.Assert.assertEqualsImpl(Assert.java:136)
at org.testng.Assert.assertEquals(Assert.java:118)
at org.testng.Assert.assertEquals(Assert.java:575)
at org.testng.Assert.assertEquals(Assert.java:585)
at itest.APITest.doCase(APITest.java:34)
at itest.APITest.run(APITest.java:25)
at sun.reflect.NativeMethodAccessorImpl.invoke0(Native Method)
at sun.reflect.NativeMethodAccessorImpl.invoke(NativeMethodAccessorImpl.java:62)
at sun.reflect.DelegatingMethodAccessorImpl.invoke(DelegatingMethodAccessorImpl.java:43)
at java.lang.reflect.Method.invoke(Method.java:498)
at org.testng.internal.MethodInvocationHelper.invokeMethod(MethodInvocationHelper.java:133)
at org.testng.internal.TestInvoker.invokeMethod(TestInvoker.java:584)
at org.testng.internal.TestInvoker.invokeTestMethod(TestInvoker.java:172)
at org.testng.internal.MethodRunner.runInSequence(MethodRunner.java:46)
at org.testng.internal.TestInvoker$MethodInvocationAgent.invoke(TestInvoker.java:804)
at org.testng.internal.TestInvoker.invokeTestMethods(TestInvoker.java:145)
at org.testng.internal.TestMethodWorker.invokeTestMethods(TestMethodWorker.java:146)
at org.testng.internal.TestMethodWorker.run(TestMethodWorker.java:128)
at java.util.ArrayList.forEach(ArrayList.java:1257)
at org.testng.TestRunner.privateRun(TestRunner.java:770)
at org.testng.TestRunner.run(TestRunner.java:591)
at org.testng.SuiteRunner.runTest(SuiteRunner.java:402)
at org.testng.SuiteRunner.runSequentially(SuiteRunner.java:396)
at org.testng.SuiteRunner.privateRun(SuiteRunner.java:355)
at org.testng.SuiteRunner.run(SuiteRunner.java:304)
at org.testng.SuiteRunnerWorker.runSuite(SuiteRunnerWorker.java:53)
at org.testng.SuiteRunnerWorker.run(SuiteRunnerWorker.java:96)
at org.testng.TestNG.runSuitesSequentially(TestNG.java:1180)
at org.testng.TestNG.runSuitesLocally(TestNG.java:1102)
at org.testng.TestNG.runSuites(TestNG.java:1032)
at org.testng.TestNG.run(TestNG.java:1000)
at org.testng.remote.AbstractRemoteTestNG.run(AbstractRemoteTestNG.java:115)
at org.testng.remote.RemoteTestNG.initAndRun(RemoteTestNG.java:251)
at org.testng.remote.RemoteTestNG.main(RemoteTestNG.java:77)
]]>
            </full-stacktrace>
          </exception> <!-- java.lang.AssertionError -->
          <reporter-output>
          </reporter-output>
        </test-method> <!-- run -->
      </class> <!-- itest.APITest -->
    </test> <!-- 用户管理系统接口 -->
  </suite> <!-- 用户管理系统 -->
</testng-results>
