<?xml version="1.0" encoding="UTF-8"?>
<!-- Generated by org.testng.reporters.JUnitXMLReporter -->
<testsuite hostname="DESKTOP-CU28HKJ" ignored="0" name="test1" tests="4" failures="2" timestamp="2020-03-23T20:37:41 CST" time="0.137" errors="0">
  <testcase name="logDemo" time="0.015" classname="com.autotest.extentreport.ExtentReportsTest">
    <failure type="java.lang.RuntimeException" message="自己抛出的运行时异常">
      <![CDATA[java.lang.RuntimeException: 自己抛出的运行时异常
at com.autotest.extentreport.ExtentReportsTest.logDemo(ExtentReportsTest.java:27)
at java.util.ArrayList.forEach(ArrayList.java:1257)
... Removed 27 stack frames]]>
    </failure>
  </testcase> <!-- logDemo -->
  <testcase name="test1" time="0.015" classname="com.autotest.extentreport.ExtentReportsTest">
    <failure type="java.lang.AssertionError" message="expected [2] but found [1]">
      <![CDATA[java.lang.AssertionError: expected [2] but found [1]
at com.autotest.extentreport.ExtentReportsTest.test1(ExtentReportsTest.java:11)
at java.util.ArrayList.forEach(ArrayList.java:1257)
... Removed 32 stack frames]]>
    </failure>
  </testcase> <!-- test1 -->
  <testcase name="test2" time="0.012" classname="com.autotest.extentreport.ExtentReportsTest"/>
  <testcase name="test3" time="0.005" classname="com.autotest.extentreport.ExtentReportsTest"/>
</testsuite> <!-- test1 -->
